Workbook

Sheet PARAMETRES
A1: HÉROS | B1: RÔLE
A2: Son Goku Super Sayen | B2: Attaquant
A3: Piccolo | B3: Attaquant
A4: Dabra | B4: Attaquant
A5: Kale | B5: Attaquant
A6: Son Goku Mini | B6: Attaquant
A7: Bojack | B7: Attaquant
A8: Gamma 1 et 2 | B8: Attaquant
A9: C-18 | B9: Attaquant
A10: Son Goku Sayen 3 | B10: Attaquant
A11: Broly | B11: Attaquant
A12: Super Uub | B12: Attaquant
... A35: Bardock | B35: Défenseur

Sheet DATA
A1: Date | B1: Heure | C1: Résultat | D1: Xhelo | E1: J9 | F1: X_K | G1: X_D | H1: X_A | I1: J_K | J1: J_D | K1: J_A | L1: DUO
A2: 46036 | B2: 0.90555556 | C2: VICTOIRE | D2: Broly | E2: Cooler | F2: 5 | G2: 2 | H2: 8 | I2: 3 | J2: 1 | K2: 10 | L2: Broly + Cooler
A3: 46036 | B3: 0.89861111 | C3: VICTOIRE | D3: Broly | E3: Cooler | F3: 7 | G3: 0 | H3: 7 | I3: 5 | J3: 0 | K3: 5 | L3: Broly + Cooler
A4: 46036 | B4: 0.89027778 | C4: DÉFAITE | D4: Broly | E4: Trunks Jeune | F4: 0 | G4: 0 | H4: 0 | I4: 0 | J4: 0 | K4: 0 | L4: Broly + Trunks Jeune
A5: 46036 | B5: 0.88055556 | C5: DÉFAITE | D5: Buu | E5: Trunks Jeune | F5: 0 | G5: 0 | H5: 0 | I5: 0 | J5: 0 | K5: 0 | L5: Buu + Trunks Jeune
A6: 46036 | B6: 0.87083333 | C6: DÉFAITE | D6: Broly | E6: Gotenks | F6: 0 | G6: 0 | H6: 0 | I6: 0 | J6: 0 | K6: 0 | L6: Broly + Gotenks
A7: 46036 | B7: 0.86111111 | C7: DÉFAITE | D7: C-18 | E7: Gotenks | F7: 4 | G7: 8 | H7: 3 | I7: 1 | J7: 3 | K7: 3 | L7: C-18 + Gotenks
A8: 46036 | B8: 0.74444444 | C8: DÉFAITE | D8: Buu | E8: Trunks Jeune | F8: 0 | G8: 0 | H8: 0 | I8: 0 | J8: 0 | K8: 0 | L8: Buu + Trunks Jeune
A9: 46036 | B9: 0.74305556 | C9: VICTOIRE | D9: Vegeta 4 | E9: Trunks Jeune | F9: 7 | G9: 0 | H9: 5 | I9: 6 | J9: 1 | K9: 5 | L9: Vegeta 4 + Trunks Jeune
A10: 46036 | B10: 0.73194444 | C10: VICTOIRE | D10: Broly | E10: Cooler | F10: 9 | G10: 5 | H10: 0 | I10: 1 | J10: 6 | K10: 4 | L10: Broly + Cooler
A11: 46036 | B11: 0.72291667 | C11: VICTOIRE | D11: Broly | E11: Gotenks | F11: 5 | G11: 7 | H11: 8 | I11: 5 | J11: 4 | K11: 7 | L11: Broly + Gotenks
A12: 46036 | B12: 0.70416667 | C12: VICTOIRE | D12: Buu | E12: Trunks Jeune | F12: 0 | G12: 0 | H12: 0 | I12: 0 | J12: 0 | K12: 0 | L12: Buu + Trunks Jeune
A13: 46036 | B13: 0.69861111 | C13: VICTOIRE | D13: Broly | E13: Gotenks | F13: 0 | G13: 0 | H13: 0 | I13: 0 | J13: 0 | K13: 0 | L13: Broly + Gotenks
... A32: 46037 | B32: 0.86180556 | C32: VICTOIRE | D32: Cell | E32: Trunks Jeune | F32: 0 | G32: 1 | H32: 7 | I32: 7 | J32: 0 | K32: 1 | L32: Cell + Trunks Jeune
A33: 46037 | B33: 0.87986111 | C33: DÉFAITE | D33: Broly | E33: Cooler | F33: 7 | G33: 1 | H33: 4 | I33: 6 | K33: 4 | L33: Broly + Cooler
A34: 46037 | B34: 0.89513889 | C34: DÉFAITE | D34: Broly | E34: Gotenks | F34: 0 | G34: 0 | H34: 0 | I34: 0 | J34: 0 | K34: 0 | L34: Broly + Gotenks
A35: 46037 | B35: 0.90694444 | C35: VICTOIRE | D35: Cell | E35: Trunks Jeune | F35: 4 | G35: 2 | H35: 1 | I35: 4 | J35: 3 | K35: 1 | L35: Cell + Trunks Jeune
A36: 46037 | B36: 0.91805556 | C36: DÉFAITE | D36: Cell | E36: Trunks Jeune | F36: 1 | G36: 3 | H36: 0 | I36: 2 | J36: 2 | K36: 1 | L36: Cell + Trunks Jeune
A37: 46037 | B37: 0.92777778 | C37: DÉFAITE | D37: Broly | E37: Trunks Jeune | F37: 2 | G37: 5 | H37: 3 | I37: 3 | J37: 3 | K37: 2 | L37: Broly + Trunks Jeune
A38: 46038 | B38: 0.75694444 | C38: VICTOIRE | D38: Buu | E38: Cooler | F38: 3 | G38: 0 | H38: 10 | I38: 1 | J38: 0 | K38: 8 | L38: Buu + Cooler
A39: 46038 | B39: 0.76666667 | C39: VICTOIRE | D39: Son Goku Super Sayen | E39: Cooler | F39: 11 | G39: 4 | H39: 3 | I39: 0 | J39: 5 | K39: 13 | L39: Son Goku Super Sayen + Cooler
A40: 46039 | B40: 0.46875 | C40: VICTOIRE | D40: Cell | E40: Trunks Jeune | F40: 4 | G40: 0 | H40: 0 | I40: 2 | J40: 1 | K40: 0 | L40: Cell + Trunks Jeune
A41: 46039 | B41: 0.70694444 | C41: DÉFAITE | D41: cell | E41: Trunks Jeune | F41: 4 | G41: 2 | H41: 2 | I41: 1 | J41: 3 | K41: 4 | L41: Cell + Trunks Jeune
A42: 46039 | B42: 0.72916667 | C42: DÉFAITE | D42: Broly | E42: Gotenks | F42: 7 | G42: 3 | H42: 1 | I42: 3 | J42: 1 | K42: 7 | L42: Gotenks + Broly
A43: 46040 | B43: 0.32291667 | C43: VICTOIRE | D43: Broly | E43: Cooler | F43: 10 | G43: 6 | H43: 6 | I43: 2 | J43: 5 | K43: 7 | L43: Broly + Cooler
A44: 46040 | B44: 0.33402778 | C44: VICTOIRE | D44: Broly | E44: Ultimate Gohan | F44: 9 | G44: 3 | H44: 2 | I44: 4 | J44: 5 | K44: 5 | L44: Broly + Ultimate Gohan
A45: 46040 | B45: 0.34513889 | C45: VICTOIRE | D45: Cooler | E45: Trunks Jeune | F45: 1 | G45: 3 | H45: 3 | I45: 3 | J45: 1 | K45: 1 | L45: Cooler + Trunks Jeune
... A100: 46056 | B100: 0.90972222 | C100: DEFAITE | D100: Broly | E100: Trunks Jeune | F100: 1 | G100: 5 | H100: 1 | I100: 3 | J100: 4 | K100: 0 | L100: Broly + Trunks jeune
A101: 46057 | B101: 0.56944444 | C101: VICTOIRE | D101: Bardock | E101: Vegito | F101: 3 | G101: 0 | H101: 10 | I101: 13 | J101: 0 | K101: 3 | L101: Bardock + Vegito | N101: 100 ème match! | O101: et une win !
A102: 46057 | B102: 0.59444444 | C102: VICTOIRE | D102: Bardock | E102: Vegito | F102: 2 | G102: 1 | H102: 10 | I102: 7 | J102: 1 | K102: 4 | L102: Bardock + Vegito
A103: 46057 | B103: 0.59722222 | C103: VICTOIRE | D103: Bardock | E103: Vegito | F103: 0 | G103: 0 | H103: 7 | I103: 5 | J103: 2 | K103: 6 | L103: Bardock + Vegito
A104: 46057 | B104: 0.60555556 | C104: VICTOIRE | D104: Bardock | E104: Vegito | F104: 1 | G104: 2 | H104: 7 | I104: 13 | J104: 1 | K104: 3 | L104: Bardock + Vegito
A105: 46057 | B105: 0.61319444 | C105: VICTOIRE | D105: Bardock | E105: Vegito | F105: 3 | G105: 0 | H105: 6 | I105: 7 | J105: 0 | K105: 3 | L105: Bardock + Vegito
A106: 46057 | B106: 0.62083333 | C106: VICTOIRE | D106: Bardock | E106: Vegito | F106: 2 | G106: 3 | H106: 5 | I106: 8 | J106: 2 | K106: 6 | L106: Bardock + Vegito
A107: 46057 | B107: 0.62777778 | C107: VICTOIRE | D107: Bardock | E107: Vegito | F107: 5 | G107: 0 | H107: 10 | I107: 7 | J107: 1 | K107: 9 | L107: Bardock + Vegito
A108: 46057 | B108: 0.63958333 | C108: VICTOIRE | D108: Bardock | E108: Vegito | F108: 3 | G108: 1 | H108: 10 | I108: 12 | J108: 3 | K108: 2 | L108: Bardock + Vegito
A109: 46057 | B109: 0.64722222 | C109: VICTOIRE | D109: Bardock | E109: Vegito | F109: 2 | G109: 0 | H109: 7 | I109: 4 | J109: 0 | K109: 4 | L109: Bardock + Vegito
A110: 46057 | B110: 0.65694444 | C110: DEFAITE | D110: Bardock | E110: Vegito | F110: 0 | G110: 3 | H110: 8 | I110: 8 | J110: 1 | K110: 3 | L110: Bardock + Vegito
A111: 46057 | B111: 0.66597222 | C111: VICTOIRE | D111: Bardock | E111: Vegito | F111: 3 | G111: 0 | H111: 4 | I111: 5 | J111: 3 | K111: 7 | L111: Bardock + Vegito
A112: 46057 | B112: 0.67708333 | C112: VICTOIRE | D112: Bardock | E112: Vegito | F112: 3 | G112: 1 | H112: 4 | I112: 4 | J112: 0 | K112: 7 | L112: Bardock + Vegito
...

Sheet CALCULS
A1: KPI | B1: VAL
B2: =COUNTA(TableData[Date]) -> 169
B3: =COUNTIF(TableData[Résultat],"VICTOIRE") -> 104
B4: =IF(B2>0, B3/B2, 0) -> 0.61538462
A9: HERO_REF | B9: WINS | C9: PLAYED | D9: RATE | E9: SCORE | F9: ROLE | G9: RANK | H9: SSCORE | I9: SNAME | J9: DNAME | K9: SRATE | L9: DEFEATS | R9: DUO_REF | S9: WINS | T9: PLAYED | U9: RATE | V9: SCORE | W9: DEFEATS | AF9: XW | AG9: XP | AH9: XR | AI9: XL | AJ9: XS | AK9: XK | AL9: XD | AM9: XA | AN9: XKDAR | AO9: XKDAS | AQ9: JW | AR9: JP | AS9: JR | AT9: JL | AU9: JS | AV9: JK | AW9: JD | AX9: JA | AY9: JKDAR | AZ9: JKDAS | BA9: ROLE | BB9: XRW | BC9: XRP | BD9: XR_RATE | BE9: XR_LOSS | BF9: JRW | BG9: JRP | BH9: JR_RATE | BI9: JR_LOSS | BJ9: XKA | BK9: XDA | BL9: XAA | BM9: JKA | BN9: JDA | BO9: JAA
A10: =IF(PARAMETRES!A2="", 0, PARAMETRES!A2) -> Son Goku Super Sayen | B10: =IF(A10=0, 0, COUNTIFS(TableData[Résultat], "VICTOIRE", TableData[Xhelo], A10) + COUNTIFS(TableData[Résultat], "VICTOIRE", TableData[J9], A10)) -> 6 | C10: =IF(A10=0, 0, COUNTIF(TableData[Xhelo], A10) + COUNTIF(TableData[J9], A10)) -> 7 | D10: =IF(C10>0, B10/C10, 0) -> 0.85714286 | E10: =IF(C10>0, INT(D10*10000000) + (B10*1000) + (100-ROW()), -1) -> 8577518 | F10: =IF(A10=0, 0, PARAMETRES!B2) -> Attaquant | G10: 1 | H10: =LARGE(E$10:E$60, G10) -> 8577518 | I10: =IF(H10>-1, INDEX(A$10:A$60, MATCH(H10, E$10:E$60, 0)), "") -> Son Goku Super Sayen | J10: =IF(I10<>"", I10 & " (" & SUMIF(A$10:A$60, I10, B$10:B$60) & "V - " & SUMIF(A$10:A$60, I10, L$10:L$60) & "D)", "") -> Son Goku Super Sayen (6V - 1D) | K10: =IF(I10<>"", SUMIF(A$10:A$60, I10, D$10:D$60), 0) -> 0.85714286 | L10: =C10-B10 -> 1 | N10: =IF(DATA!L2="", "", DATA!L2) -> Broly + Cooler | O10: =IF(N10="", "", IF(COUNTIF(N$10:N10, N10)=1, ROW(), "")) -> 10 | P10: =IFERROR(SMALL(O$10:O$500, 1), "") -> 10 | R10: =IF(P10="", 0, INDEX(N$10:N$500, P10-9)) -> Broly + Cooler | S10: =IF(R10=0, 0, COUNTIFS(TableData[Résultat], "VICTOIRE", TableData[DUO], R10)) -> 7 | T10: =IF(R10=0, 0, COUNTIF(TableData[DUO], R10)) -> 11 | U10: =IF(T10>0, S10/T10, 0) -> 0.63636364 | V10: =IF(T10>0, INT(U10*10000000) + (S10*1000) + (10000-ROW()), -1) -> 6380626 | Y10: =T10-S10 -> 4 | Z10: 1 | AA10: =LARGE(V$10:V$60, Z10) -> 10014982 | AB10: =IF(AA10>-1, INDEX(R$10:R$60, MATCH(AA10, V$10:V$60, 0)), "") -> Son Goku Super Sayen + Cooler | AC10: =IF(AB10<>"", AB10 & " (" & SUMIF(R$10:R$60, AB10, S$10:S$60) & "V - " & SUMIF(R$10:R$60, AB10, Y$10:Y$60) & "D)", "") -> Son Goku Super Sayen + Cooler (5V - 0D) | AD10: =IF(AB10<>"", SUMIF(R$10:R$60, AB10, U$10:U$60), 0) -> 1 | AF10: =IF(A10=0, 0, COUNTIFS(TableData[Résultat], "VICTOIRE", TableData[Xhelo], A10)) -> 6 | AG10: =IF(A10=0, 0, COUNTIF(TableData[Xhelo], A10)) -> 7 | AH10: =IF(AG10>0, AF10/AG10, 0) -> 0.85714286 | AI10: =AG10-AF10 -> 1 | AJ10: =IF(AG10>0, INT(AH10*10000000) + (AF10*1000) + (100-ROW()), -1) -> 8577518 | AK10: =SUMIF(TableData[Xhelo], A10, TableData[X_K]) -> 45 | AL10: =SUMIF(TableData[Xhelo], A10, TableData[X_D]) -> 27 | AM10: =SUMIF(TableData[Xhelo], A10, TableData[X_A]) -> 31 | AN10: =IF(AG10>0, (AK10+AM10)/MAX(1, AL10), 0) -> 2.8148148 | AO10: =IF(AG10>0, AN10*10000 + (100-ROW()), -1) -> 28238.148 | AQ10: =IF(A10=0, 0, COUNTIFS(TableData[Résultat], "VICTOIRE", TableData[J9], A10)) -> 0 | AR10: =IF(A10=0, 0, COUNTIF(TableData[J9], A10)) -> 0 | AS10: =IF(AR10>0, AQ10/AR10, 0) -> 0 | AT10: =AR10-AQ10 -> 0 | AU10: =IF(AR10>0, INT(AS10*10000000) + (AQ10*1000) + (100-ROW()), -1) -> -1 | AV10: =SUMIF(TableData[J9], A10, TableData[J_K]) -> 0 | AW10: =SUMIF(TableData[J9], A10, TableData[J_D]) -> 0 | AX10: =SUMIF(TableData[J9], A10, TableData[J_A]) -> 0 | AY10: =IF(AR10>0, (AV10+AX10)/MAX(1, AW10), 0) -> 0 | AZ10: =IF(AR10>0, AY10*10000 + (100-ROW()), -1) -> -1 | BA10: Attaquant | BB10: =SUMIF(PARAMETRES!B$2:B$60, BA10, AF$10:AF$60) -> 61 | BC10: =SUMIF(PARAMETRES!B$2:B$60, BA10, AG$10:AG$60) -> 103 | BD10: =IF(BC10>0, BB10/BC10, 0) -> 0.59223301 | BE10: =IF(BC10>0, 1-BD10, 0) -> 0.40776699 | BF10: =SUMIF(PARAMETRES!B$2:B$60, BA10, AQ$10:AQ$60) -> 45 | BG10: =SUMIF(PARAMETRES!B$2:B$60, BA10, AR$10:AR$60) -> 69 | BH10: =IF(BG10>0, BF10/BG10, 0) -> 0.65217391 | BI10: =IF(BG10>0, 1-BH10, 0) -> 0.34782609 | BJ10: =SUMIF(PARAMETRES!B$2:B$60, BA10, AK$10:AK$60)/MAX(1,BC10) -> 4.5048544 | BK10: =SUMIF(PARAMETRES!B$2:B$60, BA10, AL$10:AL$60)/MAX(1,BC10) -> 3.3592233 | BL10: =SUMIF(PARAMETRES!B$2:B$60, BA10, AM$10:AM$60)/MAX(1,BC10) -> 4.0873786 | BM10: =SUMIF(PARAMETRES!B$2:B$60, BA10, AV$10:AV$60)/MAX(1,BG10) -> 5.4637681 | BN10: =SUMIF(PARAMETRES!B$2:B$60, BA10, AW$10:AW$60)/MAX(1,BG10) -> 1.8695652 | BO10: =SUMIF(PARAMETRES!B$2:B$60, BA10, AX$10:AX$60)/MAX(1,BG10) -> 2.7536232 | CA10: 1 | CB10: =LARGE(AJ$10:AJ$60, CA10) -> 10004072 | CC10: =IF(CB10>-1, INDEX(A$10:A$60, MATCH(CB10, AJ$10:AJ$60, 0)), "") -> Cooler | CD10: =IF(CC10<>"", CC10 & " (" & SUMIF(A$10:A$60, CC10, AF$10:AF$60) & "V - " & SUMIF(A$10:A$60, CC10, AI$10:AI$60) & "D)", "") -> Cooler (4V - 0D) | CE10: =IF(CC10<>"", SUMIF(A$10:A$60, CC10, AH$10:AH$60), 0) -> 1 | CG10: 1 | CH10: =LARGE(AU$10:AU$60, CG10) -> 8024077 | CI10: =IF(CH10>-1, INDEX(A$10:A$60, MATCH(CH10, AU$10:AU$60, 0)), "") -> Vegito | CJ10: =IF(CI10<>"", CI10 & " (" & SUMIF(A$10:A$60, CI10, AQ$10:AQ$60) & "V - " & SUMIF(A$10:A$60, CI10, AT$10:AT$60) & "D)", "") -> Vegito (24V - 6D) | CK10: =IF(CI10<>"", SUMIF(A$10:A$60, CI10, AS$10:AS$60), 0) -> 0.8 | DM10: 1 | DN10: =LARGE(AO$10:AO$60, DM10) -> 52710.061 | DO10: =IF(DN10>-1, INDEX(A$10:A$60, MATCH(DN10, AO$10:AO$60, 0)), "") -> Bardock | DP10: =IF(DO10<>"", DO10 & " (" & TEXT(VLOOKUP(DO10, A$10:AO$60, 40, FALSE), "0.0") & ")", "") -> Bardock (0.5) | DQ10: =IF(DO10<>"", VLOOKUP(DO10, A$10:AO$60, 40, FALSE), 0) -> 5.2653061 | DS10: 1 | DT10: =LARGE(AZ$10:AZ$60, DS10) -> 60058 | DU10: =IF(DT10>-1, INDEX(A$10:A$60, MATCH(DT10, AZ$10:AZ$60, 0)), "") -> Kefla | DV10: =IF(DU10<>"", DU10 & " (" & TEXT(VLOOKUP(DU10, A$10:AZ$60, 51, FALSE), "0.0") & ")", "") -> Kefla (0.6) | DW10: =IF(DU10<>"", VLOOKUP(DU10, A$10:AZ$60, 51, FALSE), 0) -> 6
A11: =IF(PARAMETRES!A3="", 0, PARAMETRES!A3) -> Piccolo | B11: =IF(A11=0, 0, COUNTIFS(TableData[Résultat], "VICTOIRE", TableData[Xhelo], A11) + COUNTIFS(TableData[Résultat], "VICTOIRE", TableData[J9], A11)) -> 0 | C11: =IF(A11=0, 0, COUNTIF(TableData[Xhelo], A11) + COUNTIF(TableData[J9], A11)) -> 1 | D11: =IF(C11>0, B11/C11, 0) -> 0 | E11: =IF(C11>0, INT(D11*10000000) + (B11*1000) + (100-ROW()), -1) -> 89 | F11: =IF(A11=0, 0, PARAMETRES!B3) -> Attaquant | G11: 2 | H11: =LARGE(E$10:E$60, G11) -> 8024077 | I11: =IF(H11>-1, INDEX(A$10:A$60, MATCH(H11, E$10:E$60, 0)), "") -> Vegito | J11: =IF(I11<>"", I11 & " (" & SUMIF(A$10:A$60, I11, B$10:B$60) & "V - " & SUMIF(A$10:A$60, I11, L$10:L$60) & "D)", "") -> Vegito (24V - 0,225806451612903D) | K11: =IF(I11<>"", SUMIF(A$10:A$60, I11, D$10:D$60), 0) -> 0.8 | L11: =C11-B11 -> 1 | N11: =IF(DATA!L3="", "", DATA!L3) -> Broly + Cooler | O11: =IF(N11="", "", IF(COUNTIF(N$10:N11, N11)=1, ROW(), "")) | P11: =IFERROR(SMALL(O$10:O$500, 2), "") -> 12 | R11: =IF(P11="", 0, INDEX(N$10:N$500, P11-9)) -> Broly + Trunks Jeune | S11: =IF(R11=0, 0, COUNTIFS(TableData[Résultat], "VICTOIRE", TableData[DUO], R11)) -> 4 | T11: =IF(R11=0, 0, COUNTIF(TableData[DUO], R11)) -> 10 | U11: =IF(T11>0, S11/T11, 0) -> 0.4 | V11: =IF(T11>0, INT(U11*10000000) + (S11*1000) + (10000-ROW()), -1) -> 4013989 | Y11: =T11-S11 -> 6 | Z11: 2 | AA11: =LARGE(V$10:V$60, Z11) -> 10013979 | AB11: =IF(AA11>-1, INDEX(R$10:R$60, MATCH(AA11, V$10:V$60, 0)), "") -> Cooler + Trunks Jeune | AC11: =IF(AB11<>"", AB11 & " (" & SUMIF(R$10:R$60, AB11, S$10:S$60) & "V - " & SUMIF(R$10:R$60, AB11, Y$10:Y$60) & "D)", "") -> Cooler + Trunks Jeune (4V - 0D) | AD11: =IF(AB11<>"", SUMIF(R$10:R$60, AB11, U$10:U$60), 0) -> 1 | AF11: =IF(A11=0, 0, COUNTIFS(TableData[Résultat], "VICTOIRE", TableData[Xhelo], A11)) -> 0 | AG11: =IF(A11=0, 0, COUNTIF(TableData[Xhelo], A11)) -> 1 | AH11: =IF(AG11>0, AF11/AG11, 0) -> 0 | AI11: =AG11-AF11 -> 1 | AJ11: =IF(AG11>0, INT(AH11*10000000) + (AF11*1000) + (100-ROW()), -1) -> 89 | AK11: =SUMIF(TableData[Xhelo], A11, TableData[X_K]) -> 8 | AL11: =SUMIF(TableData[Xhelo], A11, TableData[X_D]) -> 3 | AM11: =SUMIF(TableData[Xhelo], A11, TableData[X_A]) -> 6 | AN11: =IF(AG11>0, (AK11+AM11)/MAX(1, AL11), 0) -> 4.6666667 | AO11: =IF(AG11>0, AN11*10000 + (100-ROW()), -1) -> 46755.667 | AQ11: =IF(A11=0, 0, COUNTIFS(TableData[Résultat], "VICTOIRE", TableData[J9], A11)) -> 0 | AR11: =IF(A11=0, 0, COUNTIF(TableData[J9], A11)) -> 0 | AS11: =IF(AR11>0, AQ11/AR11, 0) -> 0 | AT11: =AR11-AQ11 -> 0 | AU11: =IF(AR11>0, INT(AS11*10000000) + (AQ11*1000) + (100-ROW()), -1) -> -1 | AV11: =SUMIF(TableData[J9], A11, TableData[J_K]) -> 0 | AW11: =SUMIF(TableData[J9], A11, TableData[J_D]) -> 0 | AX11: =SUMIF(TableData[J9], A11, TableData[J_A]) -> 0 | AY11: =IF(AR11>0, (AV11+AX11)/MAX(1, AW11), 0) -> 0 | AZ11: =IF(AR11>0, AY11*10000 + (100-ROW()), -1) -> -1 | BA11: Défenseur | BB11: =SUMIF(PARAMETRES!B$2:B$60, BA11, AF$10:AF$60) -> 35 | BC11: =SUMIF(PARAMETRES!B$2:B$60, BA11, AG$10:AG$60) -> 48 | BD11: =IF(BC11>0, BB11/BC11, 0) -> 0.72916667 | BE11: =IF(BC11>0, 1-BD11, 0) -> 0.27083333 | BF11: =SUMIF(PARAMETRES!B$2:B$60, BA11, AQ$10:AQ$60) -> 27 | BG11: =SUMIF(PARAMETRES!B$2:B$60, BA11, AR$10:AR$60) -> 43 | BH11: =IF(BG11>0, BF11/BG11, 0) -> 0.62790698 | BI11: =IF(BG11>0, 1-BH11, 0) -> 0.37209302 | BJ11: =SUMIF(PARAMETRES!B$2:B$60, BA11, AK$10:AK$60)/MAX(1,BC11) -> 2.2708333 | BK11: =SUMIF(PARAMETRES!B$2:B$60, BA11, AL$10:AL$60)/MAX(1,BC11) -> 1.7916667 | BL11: =SUMIF(PARAMETRES!B$2:B$60, BA11, AM$10:AM$60)/MAX(1,BC11) -> 5.5 | BM11: =SUMIF(PARAMETRES!B$2:B$60, BA11, AV$10:AV$60)/MAX(1,BG11) -> 2.5813953 | BN11: =SUMIF(PARAMETRES!B$2:B$60, BA11, AW$10:AW$60)/MAX(1,BG11) -> 2.5813953 | BO11: =SUMIF(PARAMETRES!B$2:B$60, BA11, AX$10:AX$60)/MAX(1,BG11) -> 5.4186047 | CA11: 2 | CB11: =LARGE(AJ$10:AJ$60, CA11) -> 8577518 | CC11: =IF(CB11>-1, INDEX(A$10:A$60, MATCH(CB11, AJ$10:AJ$60, 0)), "") -> Son Goku Super Sayen | CD11: =IF(CC11<>"", CC11 & " (" & SUMIF(A$10:A$60, CC11, AF$10:AF$60) & "V - " & SUMIF(A$10:A$60, CC11, AI$10:AI$60) & "D)", "") -> Son Goku Super Sayen (6V - 1D) | CE11: =IF(CC11<>"", SUMIF(A$10:A$60, CC11, AH$10:AH$60), 0) -> 0.85714286 | CG11: 2 | CH11: =LARGE(AU$10:AU$60, CG11) -> 6932151 | CI11: =IF(CH11>-1, INDEX(A$10:A$60, MATCH(CH11, AU$10:AU$60, 0)), "") -> Zamasu | CJ11: =IF(CI11<>"", CI11 & " (" & SUMIF(A$10:A$60, CI11, AQ$10:AQ$60) & "V - " & SUMIF(A$10:A$60, CI11, AT$10:AT$60) & "D)", "") -> Zamasu (9V - 4D) | CK11: =IF(CI11<>"", SUMIF(A$10:A$60, CI11, AS$10:AS$60), 0) -> 0.69230769 | DM11: 2 | DN11: =LARGE(AO$10:AO$60, DM11) -> 46755.667 | DO11: =IF(DN11>-1, INDEX(A$10:A$60, MATCH(DN11, AO$10:AO$60, 0)), "") -> Piccolo | DP11: =IF(DO11<>"", DO11 & " (" & TEXT(VLOOKUP(DO11, A$10:AO$60, 40, FALSE), "0.0") & ")", "") -> Piccolo (0.5) | DQ11: =IF(DO11<>"", VLOOKUP(DO11, A$10:AO$60, 40, FALSE), 0) -> 4.6666667 | DS11: 2 | DT11: =LARGE(AZ$10:AZ$60, DS11) -> 58986.091 | DU11: =IF(DT11>-1, INDEX(A$10:A$60, MATCH(DT11, AZ$10:AZ$60, 0)), "") -> Vegito | DV11: =IF(DU11<>"", DU11 & " (" & TEXT(VLOOKUP(DU11, A$10:AZ$60, 51, FALSE), "0.0") & ")", "") -> Vegito (0.6) | DW11: =IF(DU11<>"", VLOOKUP(DU11, A$10:AZ$60, 51, FALSE), 0) -> 5.8909091
A12: =IF(PARAMETRES!A4="", 0, PARAMETRES!A4) -> Dabra | B12: =IF(A12=0, 0, COUNTIFS(TableData[Résultat], "VICTOIRE", TableData[Xhelo], A12) + COUNTIFS(TableData[Résultat], "VICTOIRE", TableData[J9], A12)) -> 0 | C12: =IF(A12=0, 0, COUNTIF(TableData[Xhelo], A12) + COUNTIF(TableData[J9], A12)) -> 0 | D12: =IF(C12>0, B12/C12, 0) -> 0 | E12: =IF(C12>0, INT(D12*10000000) + (B12*1000) + (100-ROW()), -1) -> -1 | F12: =IF(A12=0, 0, PARAMETRES!B4) -> Attaquant | G12: 3 | H12: =LARGE(E$10:E$60, G12) -> 7765992 | I12: =IF(H12>-1, INDEX(A$10:A$60, MATCH(H12, E$10:E$60, 0)), "") -> Bardock | J12: =IF(I12<>"", I12 & " (" & SUMIF(A$10:A$60, I12, B$10:B$60) & "V - " & SUMIF(A$10:A$60, I12, L$10:L$60) & "D)", "") -> Bardock (24V - 7D) | K12: =IF(I12<>"", SUMIF(A$10:A$60, I12, D$10:D$60), 0) -> 0.77419355 | L12: =C12-B12 -> 0 | N12: =IF(DATA!L4="", "", DATA!L4) -> Broly + Trunks Jeune | O12: =IF(N12="", "", IF(COUNTIF(N$10:N12, N12)=1, ROW(), "")) -> 12 | P12: =IFERROR(SMALL(O$10:O$500, 3), "") -> 13 | R12: =IF(P12="", 0, INDEX(N$10:N$500, P12-9)) -> Buu + Trunks Jeune | S12: =IF(R12=0, 0, COUNTIFS(TableData[Résultat], "VICTOIRE", TableData[DUO], R12)) -> 6 | T12: =IF(R12=0, 0, COUNTIF(TableData[DUO], R12)) -> 10 | U12: =IF(T12>0, S12/T12, 0) -> 0.6 | V12: =IF(T12>0, INT(U12*10000000) + (S12*1000) + (10000-ROW()), -1) -> 6015988 | Y12: =T12-S12 -> 4 | Z12: 3 | AA12: =LARGE(V$10:V$60, Z12) -> 10010972 | AB12: =IF(AA12>-1, INDEX(R$10:R$60, MATCH(AA12, V$10:V$60, 0)), "") -> C18 + Vegeta 4 | AC12: =IF(AB12<>"", AB12 & " (" & SUMIF(R$10:R$60, AB12, S$10:S$60) & "V - " & SUMIF(R$10:R$60, AB12, Y$10:Y$60) & "D)", "") -> C18 + Vegeta 4 (1V - 0D) | AD12: =IF(AB12<>"", SUMIF(R$10:R$60, AB12, U$10:U$60), 0) -> 1 | AF12: =IF(A12=0, 0, COUNTIFS(TableData[Résultat], "VICTOIRE", TableData[Xhelo], A12)) -> 0 | AG12: =IF(A12=0, 0, COUNTIF(TableData[Xhelo], A12)) -> 0 | AH12: =IF(AG12>0, AF12/AG12, 0) -> 0 | AI12: =AG12-AF12 -> 0 | AJ12: =IF(AG12>0, INT(AH12*10000000) + (AF12*1000) + (100-ROW()), -1) -> -1 | AK12: =SUMIF(TableData[Xhelo], A12, TableData[X_K]) -> 0 | AL12: =SUMIF(TableData[Xhelo], A12, TableData[X_D]) -> 0 | AM12: =SUMIF(TableData[Xhelo], A12, TableData[X_A]) -> 0 | AN12: =IF(AG12>0, (AK12+AM12)/MAX(1, AL12), 0) -> 0 | AO12: =IF(AG12>0, AN12*10000 + (100-ROW()), -1) -> -1 | AQ12: =IF(A12=0, 0, COUNTIFS(TableData[Résultat], "VICTOIRE", TableData[J9], A12)) -> 0 | AR12: =IF(A12=0, 0, COUNTIF(TableData[J9], A12)) -> 0 | AS12: =IF(AR12>0, AQ12/AR12, 0) -> 0 | AT12: =AR12-AQ12 -> 0 | AU12: =IF(AR12>0, INT(AS12*10000000) + (AQ12*1000) + (100-ROW()), -1) -> -1 | AV12: =SUMIF(TableData[J9], A12, TableData[J_K]) -> 0 | AW12: =SUMIF(TableData[J9], A12, TableData[J_D]) -> 0 | AX12: =SUMIF(TableData[J9], A12, TableData[J_A]) -> 0 | AY12: =IF(AR12>0, (AV12+AX12)/MAX(1, AW12), 0) -> 0 | AZ12: =IF(AR12>0, AY12*10000 + (100-ROW()), -1) -> -1 | BA12: Soutien | BB12: =SUMIF(PARAMETRES!B$2:B$60, BA12, AF$10:AF$60) -> 7 | BC12: =SUMIF(PARAMETRES!B$2:B$60, BA12, AG$10:AG$60) -> 14 | BD12: =IF(BC12>0, BB12/BC12, 0) -> 0.5 | BE12: =IF(BC12>0, 1-BD12, 0) -> 0.5 | BF12: =SUMIF(PARAMETRES!B$2:B$60, BA12, AQ$10:AQ$60) -> 32 | BG12: =SUMIF(PARAMETRES!B$2:B$60, BA12, AR$10:AR$60) -> 57 | BH12: =IF(BG12>0, BF12/BG12, 0) -> 0.56140351 | BI12: =IF(BG12>0, 1-BH12, 0) -> 0.43859649 | BJ12: =SUMIF(PARAMETRES!B$2:B$60, BA12, AK$10:AK$60)/MAX(1,BC12) -> 0.42857143 | BK12: =SUMIF(PARAMETRES!B$2:B$60, BA12, AL$10:AL$60)/MAX(1,BC12) -> 1.2142857 | BL12: =SUMIF(PARAMETRES!B$2:B$60, BA12, AM$10:AM$60)/MAX(1,BC12) -> 2.9285714 | BM12: =SUMIF(PARAMETRES!B$2:B$60, BA12, AV$10:AV$60)/MAX(1,BG12) -> 2.3333333 | BN12: =SUMIF(PARAMETRES!B$2:B$60, BA12, AW$10:AW$60)/MAX(1,BG12) -> 2.1754386 | BO12: =SUMIF(PARAMETRES!B$2:B$60, BA12, AX$10:AX$60)/MAX(1,BG12) -> 4.0350877 | CA12: 3 | CB12: =LARGE(AJ$10:AJ$60, CA12) -> 7765992 | CC12: =IF(CB12>-1, INDEX(A$10:A$60, MATCH(CB12, AJ$10:AJ$60, 0)), "") -> Bardock | CD12: =IF(CC12<>"", CC12 & " (" & SUMIF(A$10:A$60, CC12, AF$10:AF$60) & "V - " & SUMIF(A$10:A$60, CC12, AI$10:AI$60) & "D)", "") -> Bardock (24V - 7D) | CE12: =IF(CC12<>"", SUMIF(A$10:A$60, CC12, AH$10:AH$60), 0) -> 0.77419355 | CG12: 3 | CH12: =LARGE(AU$10:AU$60, CG12) -> 6513063 | CI12: =IF(CH12>-1, INDEX(A$10:A$60, MATCH(CH12, AU$10:AU$60, 0)), "") -> Hit | CJ12: =IF(CI12<>"", CI12 & " (" & SUMIF(A$10:A$60, CI12, AQ$10:AQ$60) & "V - " & SUMIF(A$10:A$60, CI12, AT$10:AT$60) & "D)", "") -> Hit (13V - 7D) | CK12: =IF(CI12<>"", SUMIF(A$10:A$60, CI12, AS$10:AS$60), 0) -> 0.65 | DM12: 3 | DN12: =LARGE(AO$10:AO$60, DM12) -> 38960.889 | DO12: =IF(DN12>-1, INDEX(A$10:A$60, MATCH(DN12, AO$10:AO$60, 0)), "") -> Cooler | DP12: =IF(DO12<>"", DO12 & " (" & TEXT(VLOOKUP(DO12, A$10:AO$60, 40, FALSE), "0.0") & ")", "") -> Cooler (0.4) | DQ12: =IF(DO12<>"", VLOOKUP(DO12, A$10:AO$60, 40, FALSE), 0) -> 3.8888889 | DS12: 3 | DT12: =LARGE(AZ$10:AZ$60, DS12) -> 44536.684 | DU12: =IF(DT12>-1, INDEX(A$10:A$60, MATCH(DT12, AZ$10:AZ$60, 0)), "") -> Hit | DV12: =IF(DU12<>"", DU12 & " (" & TEXT(VLOOKUP(DU12, A$10:AZ$60, 51, FALSE), "0.0") & ")", "") -> Hit (0.4) | DW12: =IF(DU12<>"", VLOOKUP(DU12, A$10:AZ$60, 51, FALSE), 0) -> 4.4473684
A13: =IF(PARAMETRES!A5="", 0, PARAMETRES!A5) -> Kale | B13: =IF(A13=0, 0, COUNTIFS(TableData[Résultat], "VICTOIRE", TableData[Xhelo], A13) + COUNTIFS(TableData[Résultat], "VICTOIRE", TableData[J9], A13)) -> 7 | C13: =IF(A13=0, 0, COUNTIF(TableData[Xhelo], A13) + COUNTIF(TableData[J9], A13)) -> 11 | D13: =IF(C13>0, B13/C13, 0) -> 0.63636364 | E13: =IF(C13>0, INT(D13*10000000) + (B13*1000) + (100-ROW()), -1) -> 6370723 | F13: =IF(A13=0, 0, PARAMETRES!B5) -> Attaquant | G13: 4 | H13: =LARGE(E$10:E$60, G13) -> 6941148 | I13: =IF(H13>-1, INDEX(A$10:A$60, MATCH(H13, E$10:E$60, 0)), "") -> Cooler | J13: =IF(I13<>"", I13 & " (" & SUMIF(A$10:A$60, I13, B$10:B$60) & "V - " & SUMIF(A$10:A$60, I13, L$10:L$60) & "D)", "") -> Cooler (18V - 8D) | K13: =IF(I13<>"", SUMIF(A$10:A$60, I13, D$10:D$60), 0) -> 0.69230769 | L13: =C13-B13 -> 4 | N13: =IF(DATA!L5="", "", DATA!L5) -> Buu + Trunks Jeune | O13: =IF(N13="", "", IF(COUNTIF(N$10:N13, N13)=1, ROW(), "")) -> 13 | P13: =IFERROR(SMALL(O$10:O$500, 4), "") -> 14 | R13: =IF(P13="", 0, INDEX(N$10:N$500, P13-9)) -> Broly + Gotenks | S13: =IF(R13=0, 0, COUNTIFS(TableData[Résultat], "VICTOIRE", TableData[DUO], R13)) -> 10 | T13: =IF(R13=0, 0, COUNTIF(TableData[DUO], R13)) -> 17 | U13: =IF(T13>0, S13/T13, 0) -> 0.58823529 | V13: =IF(T13>0, INT(U13*10000000) + (S13*1000) + (10000-ROW()), -1) -> 5902339 | Y13: =T13-S13 -> 7 | Z13: 4 | AA13: =LARGE(V$10:V$60, Z13) -> 8831969 | AB13: =IF(AA13>-1, INDEX(R$10:R$60, MATCH(AA13, V$10:V$60, 0)), "") -> Bardock + Vegito | AC13: =IF(AB13<>"", AB13 & " (" & SUMIF(R$10:R$60, AB13, S$10:S$60) & "V - " & SUMIF(R$10:R$60, AB13, Y$10:Y$60) & "D)", "") -> Bardock + Vegito (22V - 3D) | AD13: =IF(AB13<>"", SUMIF(R$10:R$60, AB13, U$10:U$60), 0) -> 0.88 | AF13: =IF(A13=0, 0, COUNTIFS(TableData[Résultat], "VICTOIRE", TableData[Xhelo], A13)) -> 7 | AG13: =IF(A13=0, 0, COUNTIF(TableData[Xhelo], A13)) -> 11 | AH13: =IF(AG13>0, AF13/AG13, 0) -> 0.63636364 | AI13: =AG13-AF13 -> 4 | AJ13: =IF(AG13>0, INT(AH13*10000000) + (AF13*1000) + (100-ROW()), -1) -> 6370723 | AK13: =SUMIF(TableData[Xhelo], A13, TableData[X_K]) -> 70 | AL13: =SUMIF(TableData[Xhelo], A13, TableData[X_D]) -> 33 | AM13: =SUMIF(TableData[Xhelo], A13, TableData[X_A]) -> 46 | AN13: =IF(AG13>0, (AK13+AM13)/MAX(1, AL13), 0) -> 3.5151515 | AO13: =IF(AG13>0, AN13*10000 + (100-ROW()), -1) -> 35238.515 | AQ13: =IF(A13=0, 0, COUNTIFS(TableData[Résultat], "VICTOIRE", TableData[J9], A13)) -> 0 | AR13: =IF(A13=0, 0, COUNTIF(TableData[J9], A13)) -> 0 | AS13: =IF(AR13>0, AQ13/AR13, 0) -> 0 | AT13: =AR13-AQ13 -> 0 | AU13: =IF(AR13>0, INT(AS13*10000000) + (AQ13*1000) + (100-ROW()), -1) -> -1 | AV13: =SUMIF(TableData[J9], A13, TableData[J_K]) -> 0 | AW13: =SUMIF(TableData[J9], A13, TableData[J_D]) -> 0 | AX13: =SUMIF(TableData[J9], A13, TableData[J_A]) -> 0 | AY13: =IF(AR13>0, (AV13+AX13)/MAX(1, AW13), 0) -> 0 | AZ13: =IF(AR13>0, AY13*10000 + (100-ROW()), -1) -> -1 | CA13: 4 | CB13: =LARGE(AJ$10:AJ$60, CA13) -> 6670737 | CC13: =IF(CB13>-1, INDEX(A$10:A$60, MATCH(CB13, AJ$10:AJ$60, 0)), "") -> Cell | CD13: =IF(CC13<>"", CC13 & " (" & SUMIF(A$10:A$60, CC13, AF$10:AF$60) & "V - " & SUMIF(A$10:A$60, CC13, AI$10:AI$60) & "D)", "") -> Cell (4V - 2D) | CE13: =IF(CC13<>"", SUMIF(A$10:A$60, CC13, AH$10:AH$60), 0) -> 0.66666667 | CG13: 4 | CH13: =LARGE(AU$10:AU$60, CG13) -> 6377708 | CI13: =IF(CH13>-1, INDEX(A$10:A$60, MATCH(CH13, AU$10:AU$60, 0)), "") -> Cooler | CJ13: =IF(CI13<>"", CI13 & " (" & SUMIF(A$10:A$60, CI13, AQ$10:AQ$60) & "V - " & SUMIF(A$10:A$60, CI13, AT$10:AT$60) & "D)", "") -> Cooler (14V - 8D) | CK13: =IF(CI13<>"", SUMIF(A$10:A$60, CI13, AS$10:AS$60), 0) -> 0.63636364 | DM13: 4 | DN13: =LARGE(AO$10:AO$60, DM13) -> 35238.515 | DO13: =IF(DN13>-1, INDEX(A$10:A$60, MATCH(DN13, AO$10:AO$60, 0)), "") -> Kale | DP13: =IF(DO13<>"", DO13 & " (" & TEXT(VLOOKUP(DO13, A$10:AO$60, 40, FALSE), "0.0") & ")", "") -> Kale (0.4) | DQ13: =IF(DO13<>"", VLOOKUP(DO13, A$10:AO$60, 40, FALSE), 0) -> 3.5151515 | DS13: 4 | DT13: =LARGE(AZ$10:AZ$60, DS13) -> 34160.909 | DU13: =IF(DT13>-1, INDEX(A$10:A$60, MATCH(DT13, AZ$10:AZ$60, 0)), "") -> Vegeta 4 | DV13: =IF(DU13<>"", DU13 & " (" & TEXT(VLOOKUP(DU13, A$10:AZ$60, 51, FALSE), "0.0") & ")", "") -> Vegeta 4 (0.3) | DW13: =IF(DU13<>"", VLOOKUP(DU13, A$10:AZ$60, 51, FALSE), 0) -> 3.4090909
A14: =IF(PARAMETRES!A6="", 0, PARAMETRES!A6) -> Son Goku Mini | B14: =IF(A14=0, 0, COUNTIFS(TableData[Résultat], "VICTOIRE", TableData[Xhelo], A14) + COUNTIFS(TableData[Résultat], "VICTOIRE", TableData[J9], A14)) -> 0 | C14: =IF(A14=0, 0, COUNTIF(TableData[Xhelo], A14) + COUNTIF(TableData[J9], A14)) -> 0 | D14: =IF(C14>0, B14/C14, 0) -> 0 | E14: =IF(C14>0, INT(D14*10000000) + (B14*1000) + (100-ROW()), -1) -> -1 | F14: =IF(A14=0, 0, PARAMETRES!B6) -> Attaquant | G14: 5 | H14: =LARGE(E$10:E$60, G14) -> 6932151 | I14: =IF(H14>-1, INDEX(A$10:A$60, MATCH(H14, E$10:E$60, 0)), "") -> Zamasu | J14: =IF(I14<>"", I14 & " (" & SUMIF(A$10:A$60, I14, B$10:B$60) & "V - " & SUMIF(A$10:A$60, I14, L$10:L$60) & "D)", "") -> Zamasu (9V - 0,142857142857143D) | K14: =IF(I14<>"", SUMIF(A$10:A$60, I14, D$10:D$60), 0) -> 0.69230769 | L14: =C14-B14 -> 0 | N14: =IF(DATA!L6="", "", DATA!L6) -> Broly + Gotenks | O14: =IF(N14="", "", IF(COUNTIF(N$10:N14, N14)=1, ROW(), "")) -> 14 | P14: =IFERROR(SMALL(O$10:O$500, 5), "") -> 15 | R14: =IF(P14="", 0, INDEX(N$10:N$500, P14-9)) -> C-18 + Gotenks | S14: =IF(R14=0, 0, COUNTIFS(TableData[Résultat], "VICTOIRE", TableData[DUO], R14)) -> 0 | T14: =IF(R14=0, 0, COUNTIF(TableData[DUO], R14)) -> 1 | U14: =IF(T14>0, S14/T14, 0) -> 0 | V14: =IF(T14>0, INT(U14*10000000) + (S14*1000) + (10000-ROW()), -1) -> 9986 | Y14: =T14-S14 -> 1 | Z14: 5 | AA14: =LARGE(V$10:V$60, Z14) -> 7290703 | AB14: =IF(AA14>-1, INDEX(R$10:R$60, MATCH(AA14, V$10:V$60, 0)), "") -> Broly + Hit | AC14: =IF(AB14<>"", AB14 & " (" & SUMIF(R$10:R$60, AB14, S$10:S$60) & "V - " & SUMIF(R$10:R$60, AB14, Y$10:Y$60) & "D)", "") -> Broly + Hit (8V - 3D) | AD14: =IF(AB14<>"", SUMIF(R$10:R$60, AB14, U$10:U$60), 0) -> 0.72727273 | AF14: =IF(A14=0, 0, COUNTIFS(TableData[Résultat], "VICTOIRE", TableData[Xhelo], A14)) -> 0 | AG14: =IF(A14=0, 0, COUNTIF(TableData[Xhelo], A14)) -> 0 | AH14: =IF(AG14>0, AF14/AG14, 0) -> 0 | AI14: =AG14-AF14 -> 0 | AJ14: =IF(AG14>0, INT(AH14*10000000) + (AF14*1000) + (100-ROW()), -1) -> -1 | AK14: =SUMIF(TableData[Xhelo], A14, TableData[X_K]) -> 0 | AL14: =SUMIF(TableData[Xhelo], A14, TableData[X_D]) -> 0 | AM14: =SUMIF(TableData[Xhelo], A14, TableData[X_A]) -> 0 | AN14: =IF(AG14>0, (AK14+AM14)/MAX(1, AL14), 0) -> 0 | AO14: =IF(AG14>0, AN14*10000 + (100-ROW()), -1) -> -1 | AQ14: =IF(A14=0, 0, COUNTIFS(TableData[Résultat], "VICTOIRE", TableData[J9], A14)) -> 0 | AR14: =IF(A14=0, 0, COUNTIF(TableData[J9], A14)) -> 0 | AS14: =IF(AR14>0, AQ14/AR14, 0) -> 0 | AT14: =AR14-AQ14 -> 0 | AU14: =IF(AR14>0, INT(AS14*10000000) + (AQ14*1000) + (100-ROW()), -1) -> -1 | AV14: =SUMIF(TableData[J9], A14, TableData[J_K]) -> 0 | AW14: =SUMIF(TableData[J9], A14, TableData[J_D]) -> 0 | AX14: =SUMIF(TableData[J9], A14, TableData[J_A]) -> 0 | AY14: =IF(AR14>0, (AV14+AX14)/MAX(1, AW14), 0) -> 0 | AZ14: =IF(AR14>0, AY14*10000 + (100-ROW()), -1) -> -1 | CA14: 5 | CB14: =LARGE(AJ$10:AJ$60, CA14) -> 6370723 | CC14: =IF(CB14>-1, INDEX(A$10:A$60, MATCH(CB14, AJ$10:AJ$60, 0)), "") -> Kale | CD14: =IF(CC14<>"", CC14 & " (" & SUMIF(A$10:A$60, CC14, AF$10:AF$60) & "V - " & SUMIF(A$10:A$60, CC14, AI$10:AI$60) & "D)", "") -> Kale (7V - 4D) | CE14: =IF(CC14<>"", SUMIF(A$10:A$60, CC14, AH$10:AH$60), 0) -> 0.63636364 | CG14: 5 | CH14: =LARGE(AU$10:AU$60, CG14) -> 5734364 | CI14: =IF(CH14>-1, INDEX(A$10:A$60, MATCH(CH14, AU$10:AU$60, 0)), "") -> Trunks Jeune | CJ14: =IF(CI14<>"", CI14 & " (" & SUMIF(A$10:A$60, CI14, AQ$10:AQ$60) & "V - " & SUMIF(A$10:A$60, CI14, AT$10:AT$60) & "D)", "") -> Trunks Jeune (20V - 15D) | CK14: =IF(CI14<>"", SUMIF(A$10:A$60, CI14, AS$10:AS$60), 0) -> 0.57142857 | DM14: 5 | DN14: =LARGE(AO$10:AO$60, DM14) -> 30658.235 | DO14: =IF(DN14>-1, INDEX(A$10:A$60, MATCH(DN14, AO$10:AO$60, 0)), "") -> Vegeta 4 | DP14: =IF(DO14<>"", DO14 & " (" & TEXT(VLOOKUP(DO14, A$10:AO$60, 40, FALSE), "0.0") & ")", "") -> Vegeta 4 (0.3) | DQ14: =IF(DO14<>"", VLOOKUP(DO14, A$10:AO$60, 40, FALSE), 0) -> 3.0588235 | DS14: 5 | DT14: =LARGE(AZ$10:AZ$60, DS14) -> 33675 | DU14: =IF(DT14>-1, INDEX(A$10:A$60, MATCH(DT14, AZ$10:AZ$60, 0)), "") -> Zamasu | DV14: =IF(DU14<>"", DU14 & " (" & TEXT(VLOOKUP(DU14, A$10:AZ$60, 51, FALSE), "0.0") & ")", "") -> Zamasu (0.3) | DW14: =IF(DU14<>"", VLOOKUP(DU14, A$10:AZ$60, 51, FALSE), 0) -> 3.36
A15: =IF(PARAMETRES!A7="", 0, PARAMETRES!A7) -> Bojack | B15: =IF(A15=0, 0, COUNTIFS(TableData[Résultat], "VICTOIRE", TableData[Xhelo], A15) + COUNTIFS(TableData[Résultat], "VICTOIRE", TableData[J9], A15)) -> 0 | C15: =IF(A15=0, 0, COUNTIF(TableData[Xhelo], A15) + COUNTIF(TableData[J9], A15)) -> 0 | D15: =IF(C15>0, B15/C15, 0) -> 0 | E15: =IF(C15>0, INT(D15*10000000) + (B15*1000) + (100-ROW()), -1) -> -1 | F15: =IF(A15=0, 0, PARAMETRES!B7) -> Attaquant | L15: =C15-B15 -> 0 | N15: =IF(DATA!L7="", "", DATA!L7) -> C-18 + Gotenks | O15: =IF(N15="", "", IF(COUNTIF(N$10:N15, N15)=1, ROW(), "")) -> 15 | P15: =IFERROR(SMALL(O$10:O$500, 6), "") -> 17 | R15: =IF(P15="", 0, INDEX(N$10:N$500, P15-9)) -> Vegeta 4 + Trunks Jeune | S15: =IF(R15=0, 0, COUNTIFS(TableData[Résultat], "VICTOIRE", TableData[DUO], R15)) -> 1 | T15: =IF(R15=0, 0, COUNTIF(TableData[DUO], R15)) -> 2 | U15: =IF(T15>0, S15/T15, 0) -> 0.5 | V15: =IF(T15>0, INT(U15*10000000) + (S15*1000) + (10000-ROW()), -1) -> 5010985 | Y15: =T15-S15 -> 1 | AF15: =IF(A15=0, 0, COUNTIFS(TableData[Résultat], "VICTOIRE", TableData[Xhelo], A15)) -> 0 | AG15: =IF(A15=0, 0, COUNTIF(TableData[Xhelo], A15)) -> 0 | AH15: =IF(AG15>0, AF15/AG15, 0) -> 0 | AI15: =AG15-AF15 -> 0 | AJ15: =IF(AG15>0, INT(AH15*10000000) + (AF15*1000) + (100-ROW()), -1) -> -1 | AK15: =SUMIF(TableData[Xhelo], A15, TableData[X_K]) -> 0 | AL15: =SUMIF(TableData[Xhelo], A15, TableData[X_D]) -> 0 | AM15: =SUMIF(TableData[Xhelo], A15, TableData[X_A]) -> 0 | AN15: =IF(AG15>0, (AK15+AM15)/MAX(1, AL15), 0) -> 0 | AO15: =IF(AG15>0, AN15*10000 + (100-ROW()), -1) -> -1 | AQ15: =IF(A15=0, 0, COUNTIFS(TableData[Résultat], "VICTOIRE", TableData[J9], A15)) -> 0 | AR15: =IF(A15=0, 0, COUNTIF(TableData[J9], A15)) -> 0 | AS15: =IF(AR15>0, AQ15/AR15, 0) -> 0 | AT15: =AR15-AQ15 -> 0 | AU15: =IF(AR15>0, INT(AS15*10000000) + (AQ15*1000) + (100-ROW()), -1) -> -1 | AV15: =SUMIF(TableData[J9], A15, TableData[J_K]) -> 0 | AW15: =SUMIF(TableData[J9], A15, TableData[J_D]) -> 0 | AX15: =SUMIF(TableData[J9], A15, TableData[J_A]) -> 0 | AY15: =IF(AR15>0, (AV15+AX15)/MAX(1, AW15), 0) -> 0 | AZ15: =IF(AR15>0, AY15*10000 + (100-ROW()), -1) -> -1
A16: =IF(PARAMETRES!A8="", 0, PARAMETRES!A8) -> Gamma 1 et 2 | B16: =IF(A16=0, 0, COUNTIFS(TableData[Résultat], "VICTOIRE", TableData[Xhelo], A16) + COUNTIFS(TableData[Résultat], "VICTOIRE", TableData[J9], A16)) -> 0 | C16: =IF(A16=0, 0, COUNTIF(TableData[Xhelo], A16) + COUNTIF(TableData[J9], A16)) -> 0 | D16: =IF(C16>0, B16/C16, 0) -> 0 | E16: =IF(C16>0, INT(D16*10000000) + (B16*1000) + (100-ROW()), -1) -> -1 | F16: =IF(A16=0, 0, PARAMETRES!B8) -> Attaquant | L16: =C16-B16 -> 0 | N16: =IF(DATA!L8="", "", DATA!L8) -> Buu + Trunks Jeune | O16: =IF(N16="", "", IF(COUNTIF(N$10:N16, N16)=1, ROW(), "")) | P16: =IFERROR(SMALL(O$10:O$500, 7), "") -> 28 | R16: =IF(P16="", 0, INDEX(N$10:N$500, P16-9)) -> Buu + Cooler | S16: =IF(R16=0, 0, COUNTIFS(TableData[Résultat], "VICTOIRE", TableData[DUO], R16)) -> 1 | T16: =IF(R16=0, 0, COUNTIF(TableData[DUO], R16)) -> 4 | U16: =IF(T16>0, S16/T16, 0) -> 0.25 | V16: =IF(T16>0, INT(U16*10000000) + (S16*1000) + (10000-ROW()), -1) -> 2510984 | Y16: =T16-S16 -> 3 | AF16: =IF(A16=0, 0, COUNTIFS(TableData[Résultat], "VICTOIRE", TableData[Xhelo], A16)) -> 0 | AG16: =IF(A16=0, 0, COUNTIF(TableData[Xhelo], A16)) -> 0 | AH16: =IF(AG16>0, AF16/AG16, 0) -> 0 | AI16: =AG16-AF16 -> 0 | AJ16: =IF(AG16>0, INT(AH16*10000000) + (AF16*1000) + (100-ROW()), -1) -> -1 | AK16: =SUMIF(TableData[Xhelo], A16, TableData[X_K]) -> 0 | AL16: =SUMIF(TableData[Xhelo], A16, TableData[X_D]) -> 0 | AM16: =SUMIF(TableData[Xhelo], A16, TableData[X_A]) -> 0 | AN16: =IF(AG16>0, (AK16+AM16)/MAX(1, AL16), 0) -> 0 | AO16: =IF(AG16>0, AN16*10000 + (100-ROW()), -1) -> -1 | AQ16: =IF(A16=0, 0, COUNTIFS(TableData[Résultat], "VICTOIRE", TableData[J9], A16)) -> 0 | AR16: =IF(A16=0, 0, COUNTIF(TableData[J9], A16)) -> 0 | AS16: =IF(AR16>0, AQ16/AR16, 0) -> 0 | AT16: =AR16-AQ16 -> 0 | AU16: =IF(AR16>0, INT(AS16*10000000) + (AQ16*1000) + (100-ROW()), -1) -> -1 | AV16: =SUMIF(TableData[J9], A16, TableData[J_K]) -> 0 | AW16: =SUMIF(TableData[J9], A16, TableData[J_D]) -> 0 | AX16: =SUMIF(TableData[J9], A16, TableData[J_A]) -> 0 | AY16: =IF(AR16>0, (AV16+AX16)/MAX(1, AW16), 0) -> 0 | AZ16: =IF(AR16>0, AY16*10000 + (100-ROW()), -1) -> -1
A17: =IF(PARAMETRES!A9="", 0, PARAMETRES!A9) -> C-18 | B17: =IF(A17=0, 0, COUNTIFS(TableData[Résultat], "VICTOIRE", TableData[Xhelo], A17) + COUNTIFS(TableData[Résultat], "VICTOIRE", TableData[J9], A17)) -> 0 | C17: =IF(A17=0, 0, COUNTIF(TableData[Xhelo], A17) + COUNTIF(TableData[J9], A17)) -> 1 | D17: =IF(C17>0, B17/C17, 0) -> 0 | E17: =IF(C17>0, INT(D17*10000000) + (B17*1000) + (100-ROW()), -1) -> 83 | F17: =IF(A17=0, 0, PARAMETRES!B9) -> Attaquant | L17: =C17-B17 -> 1 | N17: =IF(DATA!L9="", "", DATA!L9) -> Vegeta 4 + Trunks Jeune | O17: =IF(N17="", "", IF(COUNTIF(N$10:N17, N17)=1, ROW(), "")) -> 17 | P17: =IFERROR(SMALL(O$10:O$500, 8), "") -> 39 | R17: =IF(P17="", 0, INDEX(N$10:N$500, P17-9)) -> Cell + Trunks Jeune | S17: =IF(R17=0, 0, COUNTIFS(TableData[Résultat], "VICTOIRE", TableData[DUO], R17)) -> 4 | T17: =IF(R17=0, 0, COUNTIF(TableData[DUO], R17)) -> 6 | U17: =IF(T17>0, S17/T17, 0) -> 0.66666667 | V17: =IF(T17>0, INT(U17*10000000) + (S17*1000) + (10000-ROW()), -1) -> 6680649 | Y17: =T17-S17 -> 2 | AF17: =IF(A17=0, 0, COUNTIFS(TableData[Résultat], "VICTOIRE", TableData[Xhelo], A17)) -> 0 | AG17: =IF(A17=0, 0, COUNTIF(TableData[Xhelo], A17)) -> 1 | AH17: =IF(AG17>0, AF17/AG17, 0) -> 0 | AI17: =AG17-AF17 -> 1 | AJ17: =IF(AG17>0, INT(AH17*10000000) + (AF17*1000) + (100-ROW()), -1) -> 83 | AK17: =SUMIF(TableData[Xhelo], A17, TableData[X_K]) -> 4 | AL17: =SUMIF(TableData[Xhelo], A17, TableData[X_D]) -> 8 | AM17: =SUMIF(TableData[Xhelo], A17, TableData[X_A]) -> 3 | AN17: =IF(AG17>0, (AK17+AM17)/MAX(1, AL17), 0) -> 0.875 | AO17: =IF(AG17>0, AN17*10000 + (100-ROW()), -1) -> 8833 | AQ17: =IF(A17=0, 0, COUNTIFS(TableData[Résultat], "VICTOIRE", TableData[J9], A17)) -> 0 | AR17: =IF(A17=0, 0, COUNTIF(TableData[J9], A17)) -> 0 | AS17: =IF(AR17>0, AQ17/AR17, 0) -> 0 | AT17: =AR17-AQ17 -> 0 | AU17: =IF(AR17>0, INT(AS17*10000000) + (AQ17*1000) + (100-ROW()), -1) -> -1 | AV17: =SUMIF(TableData[J9], A17, TableData[J_K]) -> 0 | AW17: =SUMIF(TableData[J9], A17, TableData[J_D]) -> 0 | AX17: =SUMIF(TableData[J9], A17, TableData[J_A]) -> 0 | AY17: =IF(AR17>0, (AV17+AX17)/MAX(1, AW17), 0) -> 0 | AZ17: =IF(AR17>0, AY17*10000 + (100-ROW()), -1) -> -1
A18: =IF(PARAMETRES!A10="", 0, PARAMETRES!A10) -> Son Goku Sayen 3 | B18: =IF(A18=0, 0, COUNTIFS(TableData[Résultat], "VICTOIRE", TableData[Xhelo], A18) + COUNTIFS(TableData[Résultat], "VICTOIRE", TableData[J9], A18)) -> 0 | C18: =IF(A18=0, 0, COUNTIF(TableData[Xhelo], A18) + COUNTIF(TableData[J9], A18)) -> 0 | D18: =IF(C18>0, B18/C18, 0) -> 0 | E18: =IF(C18>0, INT(D18*10000000) + (B18*1000) + (100-ROW()), -1) -> -1 | F18: =IF(A18=0, 0, PARAMETRES!B10) -> Attaquant | L18: =C18-B18 -> 0 | N18: =IF(DATA!L10="", "", DATA!L10) -> Broly + Cooler | O18: =IF(N18="", "", IF(COUNTIF(N$10:N18, N18)=1, ROW(), "")) | P18: =IFERROR(SMALL(O$10:O$500, 9), "") -> 47 | R18: =IF(P18="", 0, INDEX(N$10:N$500, P18-9)) -> Son Goku Super Sayen + Cooler | S18: =IF(R18=0, 0, COUNTIFS(TableData[Résultat], "VICTOIRE", TableData[DUO], R18)) -> 5 | T18: =IF(R18=0, 0, COUNTIF(TableData[DUO], R18)) -> 5 | U18: =IF(T18>0, S18/T18, 0) -> 1 | V18: =IF(T18>0, INT(U18*10000000) + (S18*1000) + (10000-ROW()), -1) -> 10014982 | Y18: =T18-S18 -> 0 | AF18: =IF(A18=0, 0, COUNTIFS(TableData[Résultat], "VICTOIRE", TableData[Xhelo], A18)) -> 0 | AG18: =IF(A18=0, 0, COUNTIF(TableData[Xhelo], A18)) -> 0 | AH18: =IF(AG18>0, AF18/AG18, 0) -> 0 | AI18: =AG18-AF18 -> 0 | AJ18: =IF(AG18>0, INT(AH18*10000000) + (AF18*1000) + (100-ROW()), -1) -> -1 | AK18: =SUMIF(TableData[Xhelo], A18, TableData[X_K]) -> 0 | AL18: =SUMIF(TableData[Xhelo], A18, TableData[X_D]) -> 0 | AM18: =SUMIF(TableData[Xhelo], A18, TableData[X_A]) -> 0 | AN18: =IF(AG18>0, (AK18+AM18)/MAX(1, AL18), 0) -> 0 | AO18: =IF(AG18>0, AN18*10000 + (100-ROW()), -1) -> -1 | AQ18: =IF(A18=0, 0, COUNTIFS(TableData[Résultat], "VICTOIRE", TableData[J9], A18)) -> 0 | AR18: =IF(A18=0, 0, COUNTIF(TableData[J9], A18)) -> 0 | AS18: =IF(AR18>0, AQ18/AR18, 0) -> 0 | AT18: =AR18-AQ18 -> 0 | AU18: =IF(AR18>0, INT(AS18*10000000) + (AQ18*1000) + (100-ROW()), -1) -> -1 | AV18: =SUMIF(TableData[J9], A18, TableData[J_K]) -> 0 | AW18: =SUMIF(TableData[J9], A18, TableData[J_D]) -> 0 | AX18: =SUMIF(TableData[J9], A18, TableData[J_A]) -> 0 | AY18: =IF(AR18>0, (AV18+AX18)/MAX(1, AW18), 0) -> 0 | AZ18: =IF(AR18>0, AY18*10000 + (100-ROW()), -1) -> -1
A19: =IF(PARAMETRES!A11="", 0, PARAMETRES!A11) -> Broly | B19: =IF(A19=0, 0, COUNTIFS(TableData[Résultat], "VICTOIRE", TableData[Xhelo], A19) + COUNTIFS(TableData[Résultat], "VICTOIRE", TableData[J9], A19)) -> 48 | C19: =IF(A19=0, 0, COUNTIF(TableData[Xhelo], A19) + COUNTIF(TableData[J9], A19)) -> 83 | D19: =IF(C19>0, B19/C19, 0) -> 0.57831325 | E19: =IF(C19>0, INT(D19*10000000) + (B19*1000) + (100-ROW()), -1) -> 5831213 | F19: =IF(A19=0, 0, PARAMETRES!B11) -> Attaquant | L19: =C19-B19 -> 35 | N19: =IF(DATA!L11="", "", DATA!L11) -> Broly + Gotenks | O19: =IF(N19="", "", IF(COUNTIF(N$10:N19, N19)=1, ROW(), "")) | P19: =IFERROR(SMALL(O$10:O$500, 10), "") -> 50 | R19: =IF(P19="", 0, INDEX(N$10:N$500, P19-9)) -> Gotenks + Broly | S19: =IF(R19=0, 0, COUNTIFS(TableData[Résultat], "VICTOIRE", TableData[DUO], R19)) -> 0 | T19: =IF(R19=0, 0, COUNTIF(TableData[DUO], R19)) -> 1 | U19: =IF(T19>0, S19/T19, 0) -> 0 | V19: =IF(T19>0, INT(U19*10000000) + (S19*1000) + (10000-ROW()), -1) -> 9981 | Y19: =T19-S19 -> 1 | AF19: =IF(A19=0, 0, COUNTIFS(TableData[Résultat], "VICTOIRE", TableData[Xhelo], A19)) -> 48 | AG19: =IF(A19=0, 0, COUNTIF(TableData[Xhelo], A19)) -> 83 | AH19: =IF(AG19>0, AF19/AG19, 0) -> 0.57831325 | AI19: =AG19-AF19 -> 35 | AJ19: =IF(AG19>0, INT(AH19*10000000) + (AF19*1000) + (100-ROW()), -1) -> 5831213 | AK19: =SUMIF(TableData[Xhelo], A19, TableData[X_K]) -> 337 | AL19: =SUMIF(TableData[Xhelo], A19, TableData[X_D]) -> 275 | AM19: =SUMIF(TableData[Xhelo], A19, TableData[X_A]) -> 335 | AN19: =IF(AG19>0, (AK19+AM19)/MAX(1, AL19), 0) -> 2.4436364 | AO19: =IF(AG19>0, AN19*10000 + (100-ROW()), -1) -> 24517.364 | AQ19: =IF(A19=0, 0, COUNTIFS(TableData[Résultat], "VICTOIRE", TableData[J9], A19)) -> 0 | AR19: =IF(A19=0, 0, COUNTIF(TableData[J9], A19)) -> 0 | AS19: =IF(AR19>0, AQ19/AR19, 0) -> 0 | AT19: =AR19-AQ19 -> 0 | AU19: =IF(AR19>0, INT(AS19*10000000) + (AQ19*1000) + (100-ROW()), -1) -> -1 | AV19: =SUMIF(TableData[J9], A19, TableData[J_K]) -> 0 | AW19: =SUMIF(TableData[J9], A19, TableData[J_D]) -> 0 | AX19: =SUMIF(TableData[J9], A19, TableData[J_A]) -> 0 | AY19: =IF(AR19>0, (AV19+AX19)/MAX(1, AW19), 0) -> 0 | AZ19: =IF(AR19>0, AY19*10000 + (100-ROW()), -1) -> -1
A20: =IF(PARAMETRES!A12="", 0, PARAMETRES!A12) -> Super Uub | B20: =IF(A20=0, 0, COUNTIFS(TableData[Résultat], "VICTOIRE", TableData[Xhelo], A20) + COUNTIFS(TableData[Résultat], "VICTOIRE", TableData[J9], A20)) -> 0 | C20: =IF(A20=0, 0, COUNTIF(TableData[Xhelo], A20) + COUNTIF(TableData[J9], A20)) -> 0 | D20: =IF(C20>0, B20/C20, 0) -> 0 | E20: =IF(C20>0, INT(D20*10000000) + (B20*1000) + (100-ROW()), -1) -> -1 | F20: =IF(A20=0, 0, PARAMETRES!B12) -> Attaquant | L20: =C20-B20 -> 0 | N20: =IF(DATA!L12="", "", DATA!L12) -> Buu + Trunks Jeune | O20: =IF(N20="", "", IF(COUNTIF(N$10:N20, N20)=1, ROW(), "")) | P20: =IFERROR(SMALL(O$10:O$500, 11), "") -> 52 | R20: =IF(P20="", 0, INDEX(N$10:N$500, P20-9)) -> Broly + Ultimate Gohan | S20: =IF(R20=0, 0, COUNTIFS(TableData[Résultat], "VICTOIRE", TableData[DUO], R20)) -> 7 | T20: =IF(R20=0, 0, COUNTIF(TableData[DUO], R20)) -> 15 | U20: =IF(T20>0, S20/T20, 0) -> 0.46666667 | V20: =IF(T20>0, INT(U20*10000000) + (S20*1000) + (10000-ROW()), -1) -> 4683646 | Y20: =T20-S20 -> 8 | AF20: =IF(A20=0, 0, COUNTIFS(TableData[Résultat], "VICTOIRE", TableData[Xhelo], A20)) -> 0 | AG20: =IF(A20=0, 0, COUNTIF(TableData[Xhelo], A20)) -> 0 | AH20: =IF(AG20>0, AF20/AG20, 0) -> 0 | AI20: =AG20-AF20 -> 0 | AJ20: =IF(AG20>0, INT(AH20*10000000) + (AF20*1000) + (100-ROW()), -1) -> -1 | AK20: =SUMIF(TableData[Xhelo], A20, TableData[X_K]) -> 0 | AL20: =SUMIF(TableData[Xhelo], A20, TableData[X_D]) -> 0 | AM20: =SUMIF(TableData[Xhelo], A20, TableData[X_A]) -> 0 | AN20: =IF(AG20>0, (AK20+AM20)/MAX(1, AL20), 0) -> 0 | AO20: =IF(AG20>0, AN20*10000 + (100-ROW()), -1) -> -1 | AQ20: =IF(A20=0, 0, COUNTIFS(TableData[Résultat], "VICTOIRE", TableData[J9], A20)) -> 0 | AR20: =IF(A20=0, 0, COUNTIF(TableData[J9], A20)) -> 0 | AS20: =IF(AR20>0, AQ20/AR20, 0) -> 0 | AT20: =AR20-AQ20 -> 0 | AU20: =IF(AR20>0, INT(AS20*10000000) + (AQ20*1000) + (100-ROW()), -1) -> -1 | AV20: =SUMIF(TableData[J9], A20, TableData[J_K]) -> 0 | AW20: =SUMIF(TableData[J9], A20, TableData[J_D]) -> 0 | AX20: =SUMIF(TableData[J9], A20, TableData[J_A]) -> 0 | AY20: =IF(AR20>0, (AV20+AX20)/MAX(1, AW20), 0) -> 0 | AZ20: =IF(AR20>0, AY20*10000 + (100-ROW()), -1) -> -1
A21: =IF(PARAMETRES!A13="", 0, PARAMETRES!A13) -> Trunks Jeune | B21: =IF(A21=0, 0, COUNTIFS(TableData[Résultat], "VICTOIRE", TableData[Xhelo], A21) + COUNTIFS(TableData[Résultat], "VICTOIRE", TableData[J9], A21)) -> 20 | C21: =IF(A21=0, 0, COUNTIF(TableData[Xhelo], A21) + COUNTIF(TableData[J9], A21)) -> 35 | D21: =IF(C21>0, B21/C21, 0) -> 0.57142857 | E21: =IF(C21>0, INT(D21*10000000) + (B21*1000) + (100-ROW()), -1) -> 5734364 | F21: =IF(A21=0, 0, PARAMETRES!B13) -> Attaquant | J21: =J14 -> Zamasu (9V - 0,142857142857143D) | K21: =K14 -> 0.69230769 | L21: =IF(J21="", 0, 1-K21) -> 0.30769231 | N21: =IF(DATA!L13="", "", DATA!L13) -> Broly + Gotenks | O21: =IF(N21="", "", IF(COUNTIF(N$10:N21, N21)=1, ROW(), "")) | P21: =IFERROR(SMALL(O$10:O$500, 12), "") -> 53 | R21: =IF(P21="", 0, INDEX(N$10:N$500, P21-9)) -> Cooler + Trunks Jeune | S21: =IF(R21=0, 0, COUNTIFS(TableData[Résultat], "VICTOIRE", TableData[DUO], R21)) -> 4 | T21: =IF(R21=0, 0, COUNTIF(TableData[DUO], R21)) -> 4 | U21: =IF(T21>0, S21/T21, 0) -> 1 | V21: =IF(T21>0, INT(U21*10000000) + (S21*1000) + (10000-ROW()), -1) -> 10013979 | Y21: =T21-S21 -> 0 | AC21: =AC14 -> Broly + Hit (8V - 3D) | AD21: =AD14 -> 0.72727273 | AE21: =IF(AC21="", 0, 1-AD21) -> 0.27272727 | AF21: =IF(A21=0, 0, COUNTIFS(TableData[Résultat], "VICTOIRE", TableData[Xhelo], A21)) -> 0 | AG21: =IF(A21=0, 0, COUNTIF(TableData[Xhelo], A21)) -> 0 | AH21: =IF(AG21>0, AF21/AG21, 0) -> 0 | AI21: =AG21-AF21 -> 0 | AJ21: =IF(AG21>0, INT(AH21*10000000) + (AF21*1000) + (100-ROW()), -1) -> -1 | AK21: =SUMIF(TableData[Xhelo], A21, TableData[X_K]) -> 0 | AL21: =SUMIF(TableData[Xhelo], A21, TableData[X_D]) -> 0 | AM21: =SUMIF(TableData[Xhelo], A21, TableData[X_A]) -> 0 | AN21: =IF(AG21>0, (AK21+AM21)/MAX(1, AL21), 0) -> 0 | AO21: =IF(AG21>0, AN21*10000 + (100-ROW()), -1) -> -1 | AQ21: =IF(A21=0, 0, COUNTIFS(TableData[Résultat], "VICTOIRE", TableData[J9], A21)) -> 20 | AR21: =IF(A21=0, 0, COUNTIF(TableData[J9], A21)) -> 35 | AS21: =IF(AR21>0, AQ21/AR21, 0) -> 0.57142857 | AT21: =AR21-AQ21 -> 15 | AU21: =IF(AR21>0, INT(AS21*10000000) + (AQ21*1000) + (100-ROW()), -1) -> 5734364 | AV21: =SUMIF(TableData[J9], A21, TableData[J_K]) -> 141 | AW21: =SUMIF(TableData[J9], A21, TableData[J_D]) -> 67 | AX21: =SUMIF(TableData[J9], A21, TableData[J_A]) -> 60 | AY21: =IF(AR21>0, (AV21+AX21)/MAX(1, AW21), 0) -> 3 | AZ21: =IF(AR21>0, AY21*10000 + (100-ROW()), -1) -> 30079 | CD21: =CD14 -> Kale (7V - 4D) | CE21: =CE14 -> 0.63636364 | CF21: =IF(CD21="", 0, 1-CE21) -> 0.36363636 | CJ21: =CJ14 -> Trunks Jeune (20V - 15D) | CK21: =CK14 -> 0.57142857 | CL21: =IF(CJ21="", 0, 1-CK21) -> 0.42857143 | DP21: =DP14 -> Vegeta 4 (0.3) | DQ21: =DQ14 -> 3.0588235 | DV21: =DV14 -> Zamasu (0.3) | DW21: =DW14 -> 3.36
A22: =IF(PARAMETRES!A14="", 0, PARAMETRES!A14) -> Toppo | B22: =IF(A22=0, 0, COUNTIFS(TableData[Résultat], "VICTOIRE", TableData[Xhelo], A22) + COUNTIFS(TableData[Résultat], "VICTOIRE", TableData[J9], A22)) -> 0 | C22: =IF(A22=0, 0, COUNTIF(TableData[Xhelo], A22) + COUNTIF(TableData[J9], A22)) -> 0 | D22: =IF(C22>0, B22/C22, 0) -> 0 | E22: =IF(C22>0, INT(D22*10000000) + (B22*1000) + (100-ROW()), -1) -> -1 | F22: =IF(A22=0, 0, PARAMETRES!B14) -> Attaquant | J22: =J13 -> Cooler (18V - 8D) | K22: =K13 -> 0.69230769 | L22: =IF(J22="", 0, 1-K22) -> 0.30769231 | N22: =IF(DATA!L14="", "", DATA!L14) -> Broly + Gotenks | O22: =IF(N22="", "", IF(COUNTIF(N$10:N22, N22)=1, ROW(), "")) | P22: =IFERROR(SMALL(O$10:O$500, 13), "") | R22: Kale + Cooler | S22: =IF(R22=0, 0, COUNTIFS(TableData[Résultat], "VICTOIRE", TableData[DUO], R22)) -> 2 | T22: =IF(R22=0, 0, COUNTIF(TableData[DUO], R22)) -> 3 | U22: =IF(T22>0, S22/T22, 0) -> 0.66666667 | V22: =IF(T22>0, INT(U22*10000000) + (S22*1000) + (10000-ROW()), -1) -> 6678644 | Y22: =T22-S22 -> 1 | AC22: =AC13 -> Bardock + Vegito (22V - 3D) | AD22: =AD13 -> 0.88 | AE22: =IF(AC22="", 0, 1-AD22) -> 0.12 | AF22: =IF(A22=0, 0, COUNTIFS(TableData[Résultat], "VICTOIRE", TableData[Xhelo], A22)) -> 0 | AG22: =IF(A22=0, 0, COUNTIF(TableData[Xhelo], A22)) -> 0 | AH22: =IF(AG22>0, AF22/AG22, 0) -> 0 | AI22: =AG22-AF22 -> 0 | AJ22: =IF(AG22>0, INT(AH22*10000000) + (AF22*1000) + (100-ROW()), -1) -> -1 | AK22: =SUMIF(TableData[Xhelo], A22, TableData[X_K]) -> 0 | AL22: =SUMIF(TableData[Xhelo], A22, TableData[X_D]) -> 0 | AM22: =SUMIF(TableData[Xhelo], A22, TableData[X_A]) -> 0 | AN22: =IF(AG22>0, (AK22+AM22)/MAX(1, AL22), 0) -> 0 | AO22: =IF(AG22>0, AN22*10000 + (100-ROW()), -1) -> -1 | AQ22: =IF(A22=0, 0, COUNTIFS(TableData[Résultat], "VICTOIRE", TableData[J9], A22)) -> 0 | AR22: =IF(A22=0, 0, COUNTIF(TableData[J9], A22)) -> 0 | AS22: =IF(AR22>0, AQ22/AR22, 0) -> 0 | AT22: =AR22-AQ22 -> 0 | AU22: =IF(AR22>0, INT(AS22*10000000) + (AQ22*1000) + (100-ROW()), -1) -> -1 | AV22: =SUMIF(TableData[J9], A22, TableData[J_K]) -> 0 | AW22: =SUMIF(TableData[J9], A22, TableData[J_D]) -> 0 | AX22: =SUMIF(TableData[J9], A22, TableData[J_A]) -> 0 | AY22: =IF(AR22>0, (AV22+AX22)/MAX(1, AW22), 0) -> 0 | AZ22: =IF(AR22>0, AY22*10000 + (100-ROW()), -1) -> -1 | CD22: =CD13 -> Cell (4V - 2D) | CE22: =CE13 -> 0.66666667 | CF22: =IF(CD22="", 0, 1-CE22) -> 0.33333333 | CJ22: =CJ13 -> Cooler (14V - 8D) | CK22: =CK13 -> 0.63636364 | CL22: =IF(CJ22="", 0, 1-CK22) -> 0.36363636 | DP22: =DP13 -> Kale (0.4) | DQ22: =DQ13 -> 3.5151515 | DV22: =DV13 -> Vegeta 4 (0.3) | DW22: =DW13 -> 3.4090909
A23: =IF(PARAMETRES!A15="", 0, PARAMETRES!A15) -> Vegito | B23: =IF(A23=0, 0, COUNTIFS(TableData[Résultat], "VICTOIRE", TableData[Xhelo], A23) + COUNTIFS(TableData[Résultat], "VICTOIRE", TableData[J9], A23)) -> 24 | C23: =IF(A23=0, 0, COUNTIF(TableData[Xhelo], A23) + COUNTIF(TableData[J9], A23)) -> 30 | D23: =IF(C23>0, B23/C23, 0) -> 0.8 | E23: =IF(C23>0, INT(D23*10000000) + (B23*1000) + (100-ROW()), -1) -> 8024077 | F23: =IF(A23=0, 0, PARAMETRES!B15) -> Attaquant | J23: =J12 -> Bardock (24V - 7D) | K23: =K12 -> 0.77419355 | L23: =IF(J23="", 0, 1-K23) -> 0.22580645 | N23: =IF(DATA!L15="", "", DATA!L15) -> Buu + Trunks Jeune | O23: =IF(N23="", "", IF(COUNTIF(N$10:N23, N23)=1, ROW(), "")) | P23: =IFERROR(SMALL(O$10:O$500, 14), "") | R23: Kale + Hit | S23: =IF(R23=0, 0, COUNTIFS(TableData[Résultat], "VICTOIRE", TableData[DUO], R23)) -> 5 | T23: =IF(R23=0, 0, COUNTIF(TableData[DUO], R23)) -> 8 | U23: =IF(T23>0, S23/T23, 0) -> 0.625 | V23: =IF(T23>0, INT(U23*10000000) + (S23*1000) + (10000-ROW()), -1) -> 6264977 | Y23: =T23-S23 -> 3 | AC23: =AC12 -> C18 + Vegeta 4 (1V - 0D) | AD23: =AD12 -> 1 | AE23: =IF(AC23="", 0, 1-AD23) -> 0 | AF23: =IF(A23=0, 0, COUNTIFS(TableData[Résultat], "VICTOIRE", TableData[Xhelo], A23)) -> 0 | AG23: =IF(A23=0, 0, COUNTIF(TableData[Xhelo], A23)) -> 0 | AH23: =IF(AG23>0, AF23/AG23, 0) -> 0 | AI23: =AG23-AF23 -> 0 | AJ23: =IF(AG23>0, INT(AH23*10000000) + (AF23*1000) + (100-ROW()), -1) -> -1 | AK23: =SUMIF(TableData[Xhelo], A23, TableData[X_K]) -> 0 | AL23: =SUMIF(TableData[Xhelo], A23, TableData[X_D]) -> 0 | AM23: =SUMIF(TableData[Xhelo], A23, TableData[X_A]) -> 0 | AN23: =IF(AG23>0, (AK23+AM23)/MAX(1, AL23), 0) -> 0 | AO23: =IF(AG23>0, AN23*10000 + (100-ROW()), -1) -> -1 | AQ23: =IF(A23=0, 0, COUNTIFS(TableData[Résultat], "VICTOIRE", TableData[J9], A23)) -> 24 | AR23: =IF(A23=0, 0, COUNTIF(TableData[J9], A23)) -> 30 | AS23: =IF(AR23>0, AQ23/AR23, 0) -> 0.8 | AT23: =AR23-AQ23 -> 6 | AU23: =IF(AR23>0, INT(AS23*10000000) + (AQ23*1000) + (100-ROW()), -1) -> 8024077 | AV23: =SUMIF(TableData[J9], A23, TableData[J_K]) -> 204 | AW23: =SUMIF(TableData[J9], A23, TableData[J_D]) -> 55 | AX23: =SUMIF(TableData[J9], A23, TableData[J_A]) -> 120 | AY23: =IF(AR23>0, (AV23+AX23)/MAX(1, AW23), 0) -> 5.8909091 | AZ23: =IF(AR23>0, AY23*10000 + (100-ROW()), -1) -> 58986.091 | CD23: =CD12 -> Bardock (24V - 7D) | CE23: =CE12 -> 0.77419355 | CF23: =IF(CD23="", 0, 1-CE23) -> 0.22580645 | CJ23: =CJ12 -> Hit (13V - 7D) | CK23: =CK12 -> 0.65 | CL23: =IF(CJ23="", 0, 1-CK23) -> 0.35 | DP23: =DP12 -> Cooler (0.4) | DQ23: =DQ12 -> 3.8888889 | DV23: =DV12 -> Hit (0.4) | DW23: =DW12 -> 4.4473684
A24: =IF(PARAMETRES!A16="", 0, PARAMETRES!A16) -> Vegeta Sayen | B24: =IF(A24=0, 0, COUNTIFS(TableData[Résultat], "VICTOIRE", TableData[Xhelo], A24) + COUNTIFS(TableData[Résultat], "VICTOIRE", TableData[J9], A24)) -> 0 | C24: =IF(A24=0, 0, COUNTIF(TableData[Xhelo], A24) + COUNTIF(TableData[J9], A24)) -> 0 | D24: =IF(C24>0, B24/C24, 0) -> 0 | E24: =IF(C24>0, INT(D24*10000000) + (B24*1000) + (100-ROW()), -1) -> -1 | F24: =IF(A24=0, 0, PARAMETRES!B16) -> Défenseur | J24: =J11 -> Vegito (24V - 0,225806451612903D) | K24: =K11 -> 0.8 | L24: =IF(J24="", 0, 1-K24) -> 0.2 | N24: =IF(DATA!L16="", "", DATA!L16) -> Buu + Trunks Jeune | O24: =IF(N24="", "", IF(COUNTIF(N$10:N24, N24)=1, ROW(), "")) | P24: =IFERROR(SMALL(O$10:O$500, 15), "") | R24: Broly + Hit | S24: =IF(R24=0, 0, COUNTIFS(TableData[Résultat], "VICTOIRE", TableData[DUO], R24)) -> 8 | T24: =IF(R24=0, 0, COUNTIF(TableData[DUO], R24)) -> 11 | U24: =IF(T24>0, S24/T24, 0) -> 0.72727273 | V24: =IF(T24>0, INT(U24*10000000) + (S24*1000) + (10000-ROW()), -1) -> 7290703 | Y24: =T24-S24 -> 3 | AC24: =AC11 -> Cooler + Trunks Jeune (4V - 0D) | AD24: =AD11 -> 1 | AE24: =IF(AC24="", 0, 1-AD24) -> 0 | AF24: =IF(A24=0, 0, COUNTIFS(TableData[Résultat], "VICTOIRE", TableData[Xhelo], A24)) -> 0 | AG24: =IF(A24=0, 0, COUNTIF(TableData[Xhelo], A24)) -> 0 | AH24: =IF(AG24>0, AF24/AG24, 0) -> 0 | AI24: =AG24-AF24 -> 0 | AJ24: =IF(AG24>0, INT(AH24*10000000) + (AF24*1000) + (100-ROW()), -1) -> -1 | AK24: =SUMIF(TableData[Xhelo], A24, TableData[X_K]) -> 0 | AL24: =SUMIF(TableData[Xhelo], A24, TableData[X_D]) -> 0 | AM24: =SUMIF(TableData[Xhelo], A24, TableData[X_A]) -> 0 | AN24: =IF(AG24>0, (AK24+AM24)/MAX(1, AL24), 0) -> 0 | AO24: =IF(AG24>0, AN24*10000 + (100-ROW()), -1) -> -1 | AQ24: =IF(A24=0, 0, COUNTIFS(TableData[Résultat], "VICTOIRE", TableData[J9], A24)) -> 0 | AR24: =IF(A24=0, 0, COUNTIF(TableData[J9], A24)) -> 0 | AS24: =IF(AR24>0, AQ24/AR24, 0) -> 0 | AT24: =AR24-AQ24 -> 0 | AU24: =IF(AR24>0, INT(AS24*10000000) + (AQ24*1000) + (100-ROW()), -1) -> -1 | AV24: =SUMIF(TableData[J9], A24, TableData[J_K]) -> 0 | AW24: =SUMIF(TableData[J9], A24, TableData[J_D]) -> 0 | AX24: =SUMIF(TableData[J9], A24, TableData[J_A]) -> 0 | AY24: =IF(AR24>0, (AV24+AX24)/MAX(1, AW24), 0) -> 0 | AZ24: =IF(AR24>0, AY24*10000 + (100-ROW()), -1) -> -1 | CD24: =CD11 -> Son Goku Super Sayen (6V - 1D) | CE24: =CE11 -> 0.85714286 | CF24: =IF(CD24="", 0, 1-CE24) -> 0.14285714 | CJ24: =CJ11 -> Zamasu (9V - 4D) | CK24: =CK11 -> 0.69230769 | CL24: =IF(CJ24="", 0, 1-CK24) -> 0.30769231 | DP24: =DP11 -> Piccolo (0.5) | DQ24: =DQ11 -> 4.6666667 | DV24: =DV11 -> Vegito (0.6) | DW24: =DW11 -> 5.8909091
A25: =IF(PARAMETRES!A17="", 0, PARAMETRES!A17) -> Zamasu | B25: =IF(A25=0, 0, COUNTIFS(TableData[Résultat], "VICTOIRE", TableData[Xhelo], A25) + COUNTIFS(TableData[Résultat], "VICTOIRE", TableData[J9], A25)) -> 9 | C25: =IF(A25=0, 0, COUNTIF(TableData[Xhelo], A25) + COUNTIF(TableData[J9], A25)) -> 13 | D25: =IF(C25>0, B25/C25, 0) -> 0.69230769 | E25: =IF(C25>0, INT(D25*10000000) + (B25*1000) + (100-ROW()), -1) -> 6932151 | F25: =IF(A25=0, 0, PARAMETRES!B17) -> Défenseur | J25: =J10 -> Son Goku Super Sayen (6V - 1D) | K25: =K10 -> 0.85714286 | L25: =IF(J25="", 0, 1-K25) -> 0.14285714 | N25: =IF(DATA!L17="", "", DATA!L17) -> Broly + Gotenks | O25: =IF(N25="", "", IF(COUNTIF(N$10:N25, N25)=1, ROW(), "")) | P25: =IFERROR(SMALL(O$10:O$500, 16), "") | R25: Broly + Zamasu | S25: =IF(R25=0, 0, COUNTIFS(TableData[Résultat], "VICTOIRE", TableData[DUO], R25)) -> 9 | T25: =IF(R25=0, 0, COUNTIF(TableData[DUO], R25)) -> 13 | U25: =IF(T25>0, S25/T25, 0) -> 0.69230769 | V25: =IF(T25>0, INT(U25*10000000) + (S25*1000) + (10000-ROW()), -1) -> 6942051 | Y25: =T25-S25 -> 4 | AC25: =AC10 -> Son Goku Super Sayen + Cooler (5V - 0D) | AD25: =AD10 -> 1 | AE25: =IF(AC25="", 0, 1-AD25) -> 0 | AF25: =IF(A25=0, 0, COUNTIFS(TableData[Résultat], "VICTOIRE", TableData[Xhelo], A25)) -> 0 | AG25: =IF(A25=0, 0, COUNTIF(TableData[Xhelo], A25)) -> 0 | AH25: =IF(AG25>0, AF25/AG25, 0) -> 0 | AI25: =AG25-AF25 -> 0 | AJ25: =IF(AG25>0, INT(AH25*10000000) + (AF25*1000) + (100-ROW()), -1) -> -1 | AK25: =SUMIF(TableData[Xhelo], A25, TableData[X_K]) -> 0 | AL25: =SUMIF(TableData[Xhelo], A25, TableData[X_D]) -> 0 | AM25: =SUMIF(TableData[Xhelo], A25, TableData[X_A]) -> 0 | AN25: =IF(AG25>0, (AK25+AM25)/MAX(1, AL25), 0) -> 0 | AO25: =IF(AG25>0, AN25*10000 + (100-ROW()), -1) -> -1 | AQ25: =IF(A25=0, 0, COUNTIFS(TableData[Résultat], "VICTOIRE", TableData[J9], A25)) -> 9 | AR25: =IF(A25=0, 0, COUNTIF(TableData[J9], A25)) -> 13 | AS25: =IF(AR25>0, AQ25/AR25, 0) -> 0.69230769 | AT25: =AR25-AQ25 -> 4 | AU25: =IF(AR25>0, INT(AS25*10000000) + (AQ25*1000) + (100-ROW()), -1) -> 6932151 | AV25: =SUMIF(TableData[J9], A25, TableData[J_K]) -> 29 | AW25: =SUMIF(TableData[J9], A25, TableData[J_D]) -> 25 | AX25: =SUMIF(TableData[J9], A25, TableData[J_A]) -> 55 | AY25: =IF(AR25>0, (AV25+AX25)/MAX(1, AW25), 0) -> 3.36 | AZ25: =IF(AR25>0, AY25*10000 + (100-ROW()), -1) -> 33675 | CD25: =CD10 -> Cooler (4V - 0D) | CE25: =CE10 -> 1 | CF25: =IF(CD25="", 0, 1-CE25) -> 0 | CJ25: =CJ10 -> Vegito (24V - 6D) | CK25: =CK10 -> 0.8 | CL25: =IF(CJ25="", 0, 1-CK25) -> 0.2 | DP25: =DP10 -> Bardock (0.5) | DQ25: =DQ10 -> 5.2653061 | DV25: =DV10 -> Kefla (0.6) | DW25: =DW10 -> 6
